<sdf version='1.7'>
  <world name='default'>
    <plugin name="set_entity_state" filename="libgazebo_ros_state.so"/>
    <light name='sun' type='directional'>
      <cast_shadows>1</cast_shadows>
      <pose>0 0 10 0 -0 0</pose>
      <diffuse>0.8 0.8 0.8 1</diffuse>
      <specular>0.2 0.2 0.2 1</specular>
      <attenuation>
        <range>1000</range>
        <constant>0.9</constant>
        <linear>0.01</linear>
        <quadratic>0.001</quadratic>
      </attenuation>
      <direction>-0.5 0.1 -0.9</direction>
      <spot>
        <inner_angle>0</inner_angle>
        <outer_angle>0</outer_angle>
        <falloff>0</falloff>
      </spot>
    </light>
    <gravity>0 0 0</gravity>
    <magnetic_field>6e-06 2.3e-05 -4.2e-05</magnetic_field>
    <atmosphere type='adiabatic'/>
    <physics type='ode'>
      <max_step_size>0.001</max_step_size>
      <real_time_factor>1</real_time_factor>
      <real_time_update_rate>1000</real_time_update_rate>
    </physics>
    <scene>
      <ambient>0.9 0.9 0.9 1</ambient>
      <background>0.7 0.7 0.7 1</background>
      <shadows>1</shadows>
    <sky>
    <clouds>
      <speed>12</speed>
    </clouds>
    </sky>
    </scene>
    <model name="purdue">
      <include>
        <uri>model://purdue</uri>
        <name>purdue</name>
      </include>
      <pose>-40 0 0 0 0 0</pose>  
    </model>

    <model name="laser_0">
      <static>false</static>
      <pose>-207 -304 1 0 0 0</pose>
      <link name="laser_link">
        <visual name="laser_visual">
          <geometry>
            <box>
              <size>5 2 2</size>
            </box>
          </geometry>
          <material>
            <ambient>0 0 0 1</ambient>
            <diffuse>0 0 0 1</diffuse>
            <specular>0 0 0 0</specular>
            <emissive>1 1 0 1</emissive>
          </material>
        </visual>
        <collision name='laser_collision'>
          <laser_retro>0</laser_retro>
          <max_contacts>10</max_contacts>
          <pose>0 0 0 0 -0 0</pose>
          <geometry>
            <box>
              <size>0.02 .01 .01</size>
            </box>
          </geometry>
        </collision>
        <sensor name="skycam" type="wideanglecamera">
          <pose>0 0 2.1 0 -1.5707 0</pose>
          <camera>
            <horizontal_fov>3.1415</horizontal_fov>
            <image>
              <width>500</width>
              <height>500</height>
            </image>
            <clip>
              <near>0.1</near>
              <far>100</far>
            </clip>
            <lens>
              <type>stereographic</type>
              <scale_to_hfov>true</scale_to_hfov>
              <cutoff_angle>3.1415</cutoff_angle>
              <env_texture_size>512</env_texture_size>
            </lens>
            <distortion>
              <k1>0.0</k1>
              <k2>0.0</k2>
              <k3>0.0</k3>
              <p1>0.0</p1>
              <p2>0.0</p2>
            </distortion>
          </camera>
          <always_on>1</always_on>
          <update_rate>1</update_rate>
          <plugin name="skycam_controller" filename="libgazebo_ros_camera.so">
            <!-- <ros>
              <namespace >skycam</namespace>
            </ros> -->
            <hack_baseline>0.07</hack_baseline>
          </plugin>
        </sensor>
        <!-- ray sensor -->
        <sensor name="sensor_ray" type="ray">
          <ray>
            <scan>
              <horizontal>
                <samples>62</samples>
                <resolution>1</resolution>
                <min_angle>0</min_angle>
                <max_angle>0</max_angle>
              </horizontal>
              <vertical>
                <samples>1</samples>
                <resolution>1</resolution>
                <min_angle>0.8</min_angle>
                <max_angle>0.8</max_angle>
              </vertical>
            </scan>
            <range>
              <min>0.05</min>
              <max>50.0</max>
            </range>
          </ray>
          <always_on>true</always_on>
          <update_rate>1000.0</update_rate>
          <plugin name="laserscan" filename="libGNSSMultipathSensorPlugin.so">
            <ros>
              <namespace>/gnss_multipath_plugin</namespace>
              <remapping>~/out:=scan</remapping>
            </ros>
            <output_type>sensor_msgs/LaserScan</output_type>
            <disableNoise>0</disableNoise>
            <origin_latitude>40.427751</origin_latitude>
            <origin_longitude>-86.912004</origin_longitude>
            <origin_altitude>0</origin_altitude>
            <date_time>15/05/2021 02:30:00</date_time>
          </plugin>
        </sensor>

      <!-- <sensor name="laser_link" type="ray">
      <visualize>1</visualize>
      <update_rate>50</update_rate>
      <ray>
        <scan>
          <horizontal>
            <samples>100</samples>
            <resolution>1</resolution>
            <min_angle>1.57</min_angle>
            <max_angle>-1.57</max_angle>
          </horizontal>
        </scan>
        <range>
          <min>0.05</min>
          <max>50.0</max>
          <resolution>0.01</resolution>
        </range>
        <noise>
          <type>gaussian</type>
          <mean>0.0</mean>
          <stddev>0.01</stddev>
        </noise>
      </ray>
      <alwaysOn>true</alwaysOn>
      <plugin filename="libgazebo_ros_ray_sensor.so" name="gazebo_ros_laser_link_controller">
        <ros>
          <remapping>~/out:=scan</remapping>
        </ros>
        <output_type>sensor_msgs/LaserScan</output_type>
      </plugin>
    </sensor> -->
        <self_collide>0</self_collide>
      </link>
    </model>
    <model name='quadcopter_1'>
      <link name='base_link'>
        <inertial>
          <pose>-0.018095 0.002495 0.18448 0 -0 0</pose>
          <mass>0.6261</mass>
          <inertia>
            <ixx>0.0016987</ixx>
            <ixy>5.47232e-06</ixy>
            <ixz>-8.71305e-05</ixz>
            <iyy>0.00153751</iyy>
            <iyz>1.20831e-05</iyz>
            <izz>0.00264341</izz>
          </inertia>
        </inertial>
        <collision name='base_link_fixed_joint_lump__quadcopter_link_collision'>
          <pose>0 0 0 0 -0 0</pose>
          <geometry>
            <mesh>
              <scale>1 1 1</scale>
              <uri>file:///home/adcl/3DR/install/quad_model_description/share/quad_model_description/meshes/base_link.stl</uri>
            </mesh>
          </geometry>
          <max_contacts>10</max_contacts>
          <surface>
            <contact>
              <ode/>
            </contact>
            <bounce/>
            <friction>
              <torsional>
                <ode/>
              </torsional>
              <ode/>
            </friction>
          </surface>
        </collision>
        <collision name='base_link_fixed_joint_lump__KinectCamera_link_collision_1'>
          <pose>0.1 0 0.125 3.14159 -0 0</pose>
          <geometry>
            <mesh>
              <scale>0.2 0.2 0.2</scale>
              <uri>file:///home/adcl/3DR/install/quad_model_description/share/quad_model_description/meshes/kinect_camera_simple.dae</uri>
            </mesh>
          </geometry>
          <max_contacts>10</max_contacts>
          <surface>
            <contact>
              <ode/>
            </contact>
            <bounce/>
            <friction>
              <torsional>
                <ode/>
              </torsional>
              <ode/>
            </friction>
          </surface>
        </collision>
        <collision name='base_link_fixed_joint_lump__imu_sensor_link_collision_2'>
          <pose>0 0 0.2 0 -0 0</pose>
          <geometry>
            <box>
              <size>0.02 0.02 0.02</size>
            </box>
          </geometry>
          <surface>
            <contact>
              <ode/>
            </contact>
            <friction>
              <ode/>
              <torsional>
                <ode/>
              </torsional>
            </friction>
            <bounce/>
          </surface>
          <max_contacts>10</max_contacts>
        </collision>
        <collision name='base_link_fixed_joint_lump__radar_sensor_link_collision_3'>
          <pose>0 0 0.225 0 -0 0</pose>
          <geometry>
            <box>
              <size>0.02 0.02 0.02</size>
            </box>
          </geometry>
          <max_contacts>10</max_contacts>
          <surface>
            <contact>
              <ode/>
            </contact>
            <bounce/>
            <friction>
              <torsional>
                <ode/>
              </torsional>
              <ode/>
            </friction>
          </surface>
        </collision>
        <visual name='base_link_fixed_joint_lump__quadcopter_link_visual'>
          <pose>0 0 0 0 -0 0</pose>
          <geometry>
            <mesh>
              <scale>1 1 1</scale>
              <uri>file:///home/adcl/3DR/install/quad_model_description/share/quad_model_description/meshes/base_link.stl</uri>
            </mesh>
          </geometry>
        </visual>
        <visual name='base_link_fixed_joint_lump__KinectCamera_link_visual_1'>
          <pose>0.1 0 0.125 3.14159 -0 0</pose>
          <geometry>
            <mesh>
              <scale>0.2 0.2 0.2</scale>
              <uri>file:///home/adcl/3DR/install/quad_model_description/share/quad_model_description/meshes/kinect_camera_simple.dae</uri>
            </mesh>
          </geometry>
        </visual>
        <visual name='base_link_fixed_joint_lump__imu_sensor_link_visual_2'>
          <pose>0 0 0.2 0 -0 0</pose>
          <geometry>
            <box>
              <size>0.02 0.02 0.02</size>
            </box>
          </geometry>
        </visual>
        <visual name='base_link_fixed_joint_lump__radar_sensor_link_visual_3'>
          <pose>0 0 0.225 0 -0 0</pose>
          <geometry>
            <box>
              <size>0.02 0.02 0.02</size>
            </box>
          </geometry>
        </visual>
        <gravity>1</gravity>
        <sensor name='imu_2' type='imu'>
          <always_on>1</always_on>
          <update_rate>2</update_rate>
          <visualize>1</visualize>
          <topic>__default_topic__</topic>
          <plugin name='imu_quadcopter_1' filename='libgazebo_ros_imu_sensor.so'>
            <topicName>/quadcopter/imu_data</topicName>
            <bodyName>imu_sensor_link</bodyName>
            <updateRateHZ>1.0</updateRateHZ>
            <gaussianNoise>0.0</gaussianNoise>
            <xyzOffset>0 0 0</xyzOffset>
            <rpyOffset>0 0 0</rpyOffset>
          </plugin>
          <pose>0 0 0.2 0 -0 0</pose>
          <imu/>
        </sensor>
        <collision name='laser_collision'>
          <laser_retro>0</laser_retro>
          <max_contacts>10</max_contacts>
          <pose>0 0 0 0 -0 0</pose>
          <geometry>
            <box>
              <size>0.02 .01 .01</size>
            </box>
          </geometry>
        </collision>
        <!-- ray sensor -->
        <sensor name="sensor_ray_quad" type="ray">
          <ray>
            <scan>
              <horizontal>
                <samples>16</samples>
                <resolution>1</resolution>
                <min_angle>0</min_angle>
                <max_angle>0</max_angle>
              </horizontal>
              <vertical>
                <samples>1</samples>
                <resolution>1</resolution>
                <min_angle>0.8</min_angle>
                <max_angle>0.8</max_angle>
              </vertical>
            </scan>
            <range>
              <min>0.05</min>
              <max>50.0</max>
            </range>
          </ray>
          <always_on>true</always_on>
          <update_rate>10.0</update_rate>
          <plugin name="laserscan_quad" filename="libGNSSMultipathSensorPlugin.so">
            <ros>
              <namespace>/gnss_multipath_quad</namespace>
              <remapping>~/out:=scan1</remapping>
            </ros>
            <output_type>sensor_msgs/LaserScan</output_type>
            <disableNoise>0</disableNoise>
            <origin_latitude>40.427751</origin_latitude>
            <origin_longitude>-86.912004</origin_longitude>
            <origin_altitude>0</origin_altitude>
          </plugin>
        </sensor>
        <self_collide>0</self_collide>
        <enable_wind>0</enable_wind>
        <kinematic>0</kinematic>
      </link>
      <joint name='propeller1_joint' type='revolute'>
        <pose relative_to='base_link'>0.119689 -0.232875 0.237083 0 -0 0</pose>
        <parent>base_link</parent>
        <child>propeller1_link</child>
        <axis>
          <xyz>0 0 1</xyz>
          <limit>
            <lower>-3.1416</lower>
            <upper>3.1416</upper>
            <effort>10</effort>
            <velocity>10</velocity>
          </limit>
          <dynamics>
            <spring_reference>0</spring_reference>
            <spring_stiffness>0</spring_stiffness>
          </dynamics>
        </axis>
      </joint>
      <link name='propeller1_link'>
        <pose relative_to='propeller1_joint'>0 0 0 0 -0 0</pose>
        <inertial>
          <pose>0 1.2e-05 0.005642 0 -0 0</pose>
          <mass>0.09</mass>
          <inertia>
            <ixx>0.00041</ixx>
            <ixy>6e-05</ixy>
            <ixz>0</ixz>
            <iyy>1e-05</iyy>
            <iyz>0</iyz>
            <izz>0.00043</izz>
          </inertia>
        </inertial>
        <collision name='propeller1_link_collision'>
          <pose>-0.119689 0.232875 -0.237083 0 -0 0</pose>
          <geometry>
            <mesh>
              <scale>1 1 1</scale>
              <uri>file:///home/adcl/3DR/install/quad_model_description/share/quad_model_description/meshes/propeller_1.stl</uri>
            </mesh>
          </geometry>
          <max_contacts>10</max_contacts>
          <surface>
            <contact>
              <ode/>
            </contact>
            <bounce/>
            <friction>
              <torsional>
                <ode/>
              </torsional>
              <ode/>
            </friction>
          </surface>
        </collision>
        <visual name='propeller1_link_visual'>
          <pose>-0.119689 0.232875 -0.237083 0 -0 0</pose>
          <geometry>
            <mesh>
              <scale>1 1 1</scale>
              <uri>file:///home/adcl/3DR/install/quad_model_description/share/quad_model_description/meshes/propeller_1.stl</uri>
            </mesh>
          </geometry>
        </visual>
        <self_collide>0</self_collide>
        <enable_wind>0</enable_wind>
        <kinematic>0</kinematic>
      </link>
      <joint name='propeller2_joint' type='revolute'>
        <pose relative_to='base_link'>0.122808 0.236981 0.236017 0 -0 0</pose>
        <parent>base_link</parent>
        <child>propeller2_link</child>
        <axis>
          <xyz>0 0 1</xyz>
          <limit>
            <lower>-3.1416</lower>
            <upper>3.1416</upper>
            <effort>10</effort>
            <velocity>10</velocity>
          </limit>
          <dynamics>
            <spring_reference>0</spring_reference>
            <spring_stiffness>0</spring_stiffness>
          </dynamics>
        </axis>
      </joint>
      <link name='propeller2_link'>
        <pose relative_to='propeller2_joint'>0 0 0 0 -0 0</pose>
        <inertial>
          <pose>0 1.3e-05 0.005644 0 -0 0</pose>
          <mass>0.09</mass>
          <inertia>
            <ixx>0.00041</ixx>
            <ixy>6e-05</ixy>
            <ixz>0</ixz>
            <iyy>1e-05</iyy>
            <iyz>0</iyz>
            <izz>0.00043</izz>
          </inertia>
        </inertial>
        <collision name='propeller2_link_collision'>
          <pose>-0.122808 -0.236981 -0.236017 0 -0 0</pose>
          <geometry>
            <mesh>
              <scale>1 1 1</scale>
              <uri>file:///home/adcl/3DR/install/quad_model_description/share/quad_model_description/meshes/propeller_2.stl</uri>
            </mesh>
          </geometry>
          <max_contacts>10</max_contacts>
          <surface>
            <contact>
              <ode/>
            </contact>
            <bounce/>
            <friction>
              <torsional>
                <ode/>
              </torsional>
              <ode/>
            </friction>
          </surface>
        </collision>
        <visual name='propeller2_link_visual'>
          <pose>-0.122808 -0.236981 -0.236017 0 -0 0</pose>
          <geometry>
            <mesh>
              <scale>1 1 1</scale>
              <uri>file:///home/adcl/3DR/install/quad_model_description/share/quad_model_description/meshes/propeller_2.stl</uri>
            </mesh>
          </geometry>
        </visual>
        <self_collide>0</self_collide>
        <enable_wind>0</enable_wind>
        <kinematic>0</kinematic>
      </link>
      <joint name='propeller3_joint' type='revolute'>
        <pose relative_to='base_link'>-0.163936 0.246701 0.235995 0 -0 0</pose>
        <parent>base_link</parent>
        <child>propeller3_link</child>
        <axis>
          <xyz>0 0 1</xyz>
          <limit>
            <lower>-3.1416</lower>
            <upper>3.1416</upper>
            <effort>10</effort>
            <velocity>10</velocity>
          </limit>
          <dynamics>
            <spring_reference>0</spring_reference>
            <spring_stiffness>0</spring_stiffness>
          </dynamics>
        </axis>
      </joint>
      <link name='propeller3_link'>
        <pose relative_to='propeller3_joint'>0 0 0 0 -0 0</pose>
        <inertial>
          <pose>0 1.3e-05 0.005644 0 -0 0</pose>
          <mass>0.09</mass>
          <inertia>
            <ixx>0.00041</ixx>
            <ixy>6e-05</ixy>
            <ixz>0</ixz>
            <iyy>1e-05</iyy>
            <iyz>0</iyz>
            <izz>0.00043</izz>
          </inertia>
        </inertial>
        <collision name='propeller3_link_collision'>
          <pose>0.163936 -0.246701 -0.235995 0 -0 0</pose>
          <geometry>
            <mesh>
              <scale>1 1 1</scale>
              <uri>file:///home/adcl/3DR/install/quad_model_description/share/quad_model_description/meshes/propeller_3.stl</uri>
            </mesh>
          </geometry>
          <max_contacts>10</max_contacts>
          <surface>
            <contact>
              <ode/>
            </contact>
            <bounce/>
            <friction>
              <torsional>
                <ode/>
              </torsional>
              <ode/>
            </friction>
          </surface>
        </collision>
        <visual name='propeller3_link_visual'>
          <pose>0.163936 -0.246701 -0.235995 0 -0 0</pose>
          <geometry>
            <mesh>
              <scale>1 1 1</scale>
              <uri>file:///home/adcl/3DR/install/quad_model_description/share/quad_model_description/meshes/propeller_3.stl</uri>
            </mesh>
          </geometry>
        </visual>
        <self_collide>0</self_collide>
        <enable_wind>0</enable_wind>
        <kinematic>0</kinematic>
      </link>
      <joint name='propeller4_joint' type='revolute'>
        <pose relative_to='base_link'>-0.167158 -0.238788 0.237096 0 -0 0</pose>
        <parent>base_link</parent>
        <child>propeller4_link</child>
        <axis>
          <xyz>0 0 1</xyz>
          <limit>
            <lower>-3.1416</lower>
            <upper>3.1416</upper>
            <effort>10</effort>
            <velocity>10</velocity>
          </limit>
          <dynamics>
            <spring_reference>0</spring_reference>
            <spring_stiffness>0</spring_stiffness>
          </dynamics>
        </axis>
      </joint>
      <link name='propeller4_link'>
        <pose relative_to='propeller4_joint'>0 0 0 0 -0 0</pose>
        <inertial>
          <pose>0 1.2e-05 0.005644 0 -0 0</pose>
          <mass>0.09</mass>
          <inertia>
            <ixx>0.00041</ixx>
            <ixy>6e-05</ixy>
            <ixz>0</ixz>
            <iyy>1e-05</iyy>
            <iyz>0</iyz>
            <izz>0.00043</izz>
          </inertia>
        </inertial>
        <collision name='propeller4_link_collision'>
          <pose>0.167158 0.238788 -0.237096 0 -0 0</pose>
          <geometry>
            <mesh>
              <scale>1 1 1</scale>
              <uri>file:///home/adcl/3DR/install/quad_model_description/share/quad_model_description/meshes/propeller_4.stl</uri>
            </mesh>
          </geometry>
          <max_contacts>10</max_contacts>
          <surface>
            <contact>
              <ode/>
            </contact>
            <bounce/>
            <friction>
              <torsional>
                <ode/>
              </torsional>
              <ode/>
            </friction>
          </surface>
        </collision>
        <visual name='propeller4_link_visual'>
          <pose>0.167158 0.238788 -0.237096 0 -0 0</pose>
          <geometry>
            <mesh>
              <scale>1 1 1</scale>
              <uri>file:///home/adcl/3DR/install/quad_model_description/share/quad_model_description/meshes/propeller_4.stl</uri>
            </mesh>
          </geometry>
        </visual>
        <self_collide>0</self_collide>
        <enable_wind>0</enable_wind>
        <kinematic>0</kinematic>
      </link>
      <pose>10 10 1 0 -0 0</pose>
    </model>
    <!-- <gui>
      <camera name="user_camera">
        <projection_type>orthographic</projection_type>
        <pose>1.5 -1.25 0 0 1.578 0</pose>
      </camera>
    </gui> -->
    <gui fullscreen='0'>
      <camera name='user_camera'>
        <pose>0 0 100 0 1.57 0</pose>
        <view_controller>orbit</view_controller>
        <projection_type>orthographic</projection_type>
        <!-- <track_visual>
          <name>virtual_cam</name>
          <follow>false</follow>
          <xyz>-10 10 10 </xyz>
          <static>false</static>
          <min_dist>1.0</min_dist>
          <max_dist>5000.0</max_dist>
        </track_visual> -->
      </camera>
    </gui>
  </world>
</sdf>
<!-- vim: set et ft=xml fenc=utf-8 ff=unix sts=0 sw=2 ts=2 : -->
